Workbook

Sheet README
B1: Solar Project Finance: Excel answer key (v1)
B2: KSA and UAE utility-scale solar PV.
B4: Colour key
B5: Blue text | C5: Hard-coded input (from a source or labelled judgment/invented)
B6: Black text | C6: Formula
B7: Green text | C7: Formula linking to another sheet
B8: Pale-yellow fill | C8: Cell awaiting formula
B9: Yellow fill | C9: Key switch (country selector)
B11: Conventions
B12: Currency | C12: USD, nominal. SAR and AED are USD-pegged (AED 3.6725 per USD).
B13: Units | C13: Capex and O&M per kWac. Specific yield per kWp (DC). Convert with the DC/AC ratio.
B14: Tariff | C14: Input in US cents/kWh. 1 US cent/kWh = $10/MWh.
B15: Periods | C15: Annual. Period 1 = financial close. Construction periods first (capex, no revenue), then operating years.
B16: Percentages | C16: Stored as fractions (0.72 shows as 72.0%).
B17: v1 simplifications | C17: Flat tariff and O&M; all capacity reaches COD together (no phased COD); pro-rata debt/equity funding during construction; interest during construction capitalised into debt; no DSRA; no tax-loss carry-forward; zakat approximated as 2.5% of profit; construction period fixed at 2 years.

Sheet Inputs
A1: Inputs
A2: Blue = input value. Column F ("Selected") is based on the country switch.
A4: Country switch | D4: UAE | E4: <- choose KSA or UAE
A6: Input | B6: Key | C6: Unit | D6: KSA | E6: UAE | F6: Selected | G6: Low | H6: High | I6: Type | J6: Basis / source
A7: Plant
A8: Capacity | B8: capacity | C8: MWac | D8: 1000 | E8: 1000 | F8: =+_xlfn.XLOOKUP($D$4,$D$6:$E$6,D8:E8) -> 1000 | I8: invented | J8: Reference size for a like-for-like comparison
A9: DC/AC ratio | B9: dc_ac_ratio | C9: x | D9: 1.3 | E9: 1.3 | F9: =+_xlfn.XLOOKUP($D$4,$D$6:$E$6,D9:E9) -> 1.3 | G9: 1.2 | H9: 1.4 | I9: judgment | J9: NREL ATB 2024 and US DOE Q1 2025 benchmark use 1.34
A10: Specific yield, year 1 | B10: specific_yield_year1 | C10: kWh/kWp | D10: 2420 | E10: 2240 | F10: =+_xlfn.XLOOKUP($D$4,$D$6:$E$6,D10:E10) -> 2240 | I10: derived | J10: KSA: Najran 1,960 fixed-tilt (Global Solar Atlas) x 1.236 uplift; UAE: Al Dhafra 4,700 GWh / 2,100 MWp (Fichtner). Test +/-10%
A11: Degradation | B11: degradation | C11: %/yr | D11: 0.005 | E11: 0.005 | F11: =+_xlfn.XLOOKUP($D$4,$D$6:$E$6,D11:E11) -> 0.005 | G11: 0.005 | H11: 0.007 | I11: public | J11: NREL median 0.5%/yr; NREL ATB baseline 0.7%/yr
A12: Construction (new in v1 skeleton)
A13: Construction period | B13: construction_years | C13: years | D13: 2 | E13: 2 | F13: =+_xlfn.XLOOKUP($D$4,$D$6:$E$6,D13:E13) -> 2 | I13: judgment | J13: Financial close to COD: Sudair ~1.5 yrs (2021-22); Shuaibah 1/2 ~1.5-2.3 yrs (Aug 2023 to Feb/Nov 2025); Khazna ~2 yrs (Jan 2026 to 2028)
A14: Capex spent in construction year 1 | B14: capex_phase_y1 | C14: % of capex | D14: 0.4 | E14: 0.4 | F14: =+_xlfn.XLOOKUP($D$4,$D$6:$E$6,D14:E14) -> 0.4 | I14: judgment | J14: Typical back-loaded spend: modules and trackers delivered late. Year 2 = remainder
A15: Capex spent in construction year 2 | B15: capex_phase_y2 | C15: % of capex | D15: 0.6 | E15: 0.6 | F15: =+_xlfn.XLOOKUP($D$4,$D$6:$E$6,D15:E15) -> 0.6 | I15: judgment | J15: Must sum to 100% with year 1 (see Checks)
A16: Costs
A17: Capex | B17: capex | C17: USD/kWac | D17: 550 | E17: 550 | F17: =+_xlfn.XLOOKUP($D$4,$D$6:$E$6,D17:E17) -> 550 | G17: 450 | H17: 725 | I17: judgment | J17: Baker Institute (Feb 2026): Saudi projects 2023-25 ~600/kW, tendered ~500/kW; upper bound IRENA (2026) Renewable power generation costs in 2025 Saudi 725/kW
A18: Fixed O&M | B18: fixed_om | C18: USD/kWac/yr | D18: 11 | E18: 11 | F18: =+_xlfn.XLOOKUP($D$4,$D$6:$E$6,D18:E18) -> 11 | G18: 9 | H18: 27 | I18: public | J18: IRENA (2026) Renewable power generation costs in 2025, Table A4 (non-OECD 11.2); upper bound US DOE Q1 2025
A19: Revenue
A20: PPA tariff | B20: ppa_tariff | C20: US cents/kWh | D20: 1.3 | E20: 1.41 | F20: =+_xlfn.XLOOKUP($D$4,$D$6:$E$6,D20:E20) -> 1.41 | I20: public | J20: KSA: NREP Round 6 (Oct 2025) 1.10-1.51; UAE: Al Ajban 1.413 (2024), range 1.35-1.70
A21: PPA term | B21: ppa_term | C21: years | D21: 35 | E21: 30 | F21: =+_xlfn.XLOOKUP($D$4,$D$6:$E$6,D21:E21) -> 30 | G21: 25 | H21: 35 | I21: public | J21: KSA: Shuaibah 1/2 35 yrs (ACWA Power); UAE: EWEC 30 yrs (Al Ajban, Khazna, Al Dhafra)
A22: Financing
A23: Gearing (debt share of capex) | B23: gearing | C23: % | D23: 0.72 | E23: 0.72 | F23: =+_xlfn.XLOOKUP($D$4,$D$6:$E$6,D23:E23) -> 0.72 | G23: 0.65 | H23: 0.8 | I23: derived | J23: Dec 2025 Saudi close: $5.9bn debt of $8.2bn
A24: Debt tenor (from COD) | B24: debt_tenor | C24: years | D24: 30 | E24: 27 | F24: =+_xlfn.XLOOKUP($D$4,$D$6:$E$6,D24:E24) -> 27 | I24: judgment | J24: PPA term minus 3-5 years; Sudair 28-year soft mini-perm
A25: All-in debt rate | B25: debt_rate | C25: % | D25: 0.061 | E25: 0.061 | F25: =+_xlfn.XLOOKUP($D$4,$D$6:$E$6,D25:E25) -> 0.061 | G25: 0.05 | H25: 0.075 | I25: judgment | J25: 3M SAIBOR 4.83% (Aug 2026) + assumed 1.25% margin
A26: Tax
A27: KSA corporate income tax | B27: ksa_cit | C27: % | D27: 0.2 | F27: =+_xlfn.XLOOKUP($D$4,$D$6:$E$6,D27:E27) -> 0 | I27: public | J27: PwC Tax Summaries: 20% on non-Saudi/non-GCC share
A28: KSA zakat | B28: ksa_zakat | C28: % | D28: 0.025 | F28: =+_xlfn.XLOOKUP($D$4,$D$6:$E$6,D28:E28) -> 0 | I28: public | J28: PwC Tax Summaries: 2.5% on Saudi/GCC share (v1: applied to profit as a proxy)
A29: Foreign ownership share (KSA) | B29: foreign_ownership_share | C29: % | D29: 0.5 | F29: =+_xlfn.XLOOKUP($D$4,$D$6:$E$6,D29:E29) -> 0 | G29: 0 | H29: 1 | I29: invented | J29: Splits profit between income tax and zakat
A30: UAE corporate tax | B30: uae_ct | C30: % | E30: 0.09 | F30: =+_xlfn.XLOOKUP($D$4,$D$6:$E$6,D30:E30) -> 0.09 | I30: public | J30: UAE CT Law: 9% above AED 375,000 (Deloitte summary)
A31: UAE tax-free threshold | B31: uae_threshold_aed | C31: AED | E31: 375000 | F31: =+_xlfn.XLOOKUP($D$4,$D$6:$E$6,D31:E31) -> 375000 | I31: public | J31: UAE CT Law
A32: AED per USD | B32: aed_per_usd | C32: AED | E32: 3.6725 | F32: =+_xlfn.XLOOKUP($D$4,$D$6:$E$6,D32:E32) -> 3.6725 | I32: public | J32: Fixed peg
A33: Valuation and targets
A34: Discount rate (nominal, after tax) | B34: discount_rate | C34: % | D34: 0.077 | E34: 0.075 | F34: =+_xlfn.XLOOKUP($D$4,$D$6:$E$6,D34:E34) -> 0.075 | G34: 0.06 | H34: 0.09 | I34: KSA public / UAE judgment | J34: Hatton et al. (2026) 2026 forecast, https://doi.org/10.5281/zenodo.18662192; UAE between that (8.3%) and IRENA (4.2% real)
A35: Project life (operating years) | B35: project_life | C35: years | D35: 35 | E35: 30 | F35: =+_xlfn.XLOOKUP($D$4,$D$6:$E$6,D35:E35) -> 30 | I35: judgment | J35: Equal to PPA term in v1
A36: Target equity IRR (for solve-for) | B36: target_equity_irr | C36: % | D36: 0.08 | E36: 0.08 | F36: =+_xlfn.XLOOKUP($D$4,$D$6:$E$6,D36:E36) -> 0.08 | I36: judgment | J36: Placeholder hurdle for the tariff solve; change freely
A37: Target minimum DSCR (for solve-for) | B37: target_min_dscr | C37: x | D37: 1.2 | E37: 1.2 | F37: =+_xlfn.XLOOKUP($D$4,$D$6:$E$6,D37:E37) -> 1.2 | I37: judgment | J37: Placeholder lender covenant for the tariff solve
A38: Scenarios (discount rate overlay)
A39: Conflict premium | B39: conflict_premium | C39: bp | D39: 70 | E39: 70 | F39: =+_xlfn.XLOOKUP($D$4,$D$6:$E$6,D39:E39) -> 70 | I39: judgment | J39: Sovereign spreads +25-50 bp plus ~30 bp Treasuries (AGBI, Aug 2026)
A40: Severe scenario premium | B40: severe_premium | C40: bp | D40: 130 | E40: 130 | F40: =+_xlfn.XLOOKUP($D$4,$D$6:$E$6,D40:E40) -> 130 | I40: judgment | J40: Spreads to top of range + Treasuries + lender repricing

Sheet Timeline
A1: Timeline
A2: Flags that switch each period on or off. Period 1 = financial close.
A4: Line (period number across) | B4: Unit | C4: Total / value | D4: Spec note | E4: 1 | F4: 2 | G4: 3 | H4: 4 | I4: 5 | J4: 6 | K4: 7 | L4: 8 | M4: 9 | N4: 10 | O4: 11 | P4: 12 | Q4: 13 | R4: 14 | S4: 15 | T4: 16 | U4: 17 | V4: 18 | W4: 19 | X4: 20 | Y4: 21 | Z4: 22 | AA4: 23 | AB4: 24 | AC4: 25 | AD4: 26 | AE4: 27 | AF4: 28 | AG4: 29 | AH4: 30 | AI4: 31 | AJ4: 32 | AK4: 33 | AL4: 34 | AM4: 35 | AN4: 36 | AO4: 37 | AP4: 38 | AQ4: 39 | AR4: 40 | AS4: 41 | AT4: 42 | AU4: 43 | AV4: 44 | AW4: 45
A5: Period flags
A6: Construction flag | B6: 1/0 | C6: =+SUM(E6:AW6) -> 2 | D6: Period <= construction years | E6: =IF(E$4<=$C$7,1,0) -> 1 | F6: =IF(F$4<=$C$7,1,0) -> 1 | G6: =IF(G$4<=$C$7,1,0) -> 0 | H6: =IF(H$4<=$C$7,1,0) -> 0 | I6: =IF(I$4<=$C$7,1,0) -> 0 | J6: =IF(J$4<=$C$7,1,0) -> 0 | K6: =IF(K$4<=$C$7,1,0) -> 0 | L6: =IF(L$4<=$C$7,1,0) -> 0 | ... AW6: =IF(AW$4<=$C$7,1,0) -> 0
A7: Construction year number | B7: # | C7: =+Inputs!$F$13 -> 2 | D7: 1, 2 during construction | E7: =IF(E$4<=$C$7,E6,0) -> 1 | F7: =IF(F$4<=$C$7,E7+F6,0) -> 2 | G7: =IF(G$4<=$C$7,F7+G6,0) -> 0 | H7: =IF(H$4<=$C$7,G7+H6,0) -> 0 | I7: =IF(I$4<=$C$7,H7+I6,0) -> 0 | J7: =IF(J$4<=$C$7,I7+J6,0) -> 0 | K7: =IF(K$4<=$C$7,J7+K6,0) -> 0 | L7: =IF(L$4<=$C$7,K7+L6,0) -> 0 | M7: =IF(M$4<=$C$7,L7+M6,0) -> 0 | ... AW7: =IF(AW$4<=$C$7,AV7+AW6,0) -> 0
A8: Operations flag | B8: 1/0 | C8: =+SUM(E8:AW8) -> 30 | D8: After construction, up to PPA term | E8: =+IF(AND(E$6=0,(E$4-$C$7)<=$C$9),1,0) -> 0 | F8: =+IF(AND(F$6=0,(F$4-$C$7)<=$C$9),1,0) -> 0 | G8: =+IF(AND(G$6=0,(G$4-$C$7)<=$C$9),1,0) -> 1 | H8: =+IF(AND(H$6=0,(H$4-$C$7)<=$C$9),1,0) -> 1 | I8: =+IF(AND(I$6=0,(I$4-$C$7)<=$C$9),1,0) -> 1 | J8: =+IF(AND(J$6=0,(J$4-$C$7)<=$C$9),1,0) -> 1 | K8: =+IF(AND(K$6=0,(K$4-$C$7)<=$C$9),1,0) -> 1 | L8: =+IF(AND(L$6=0,(L$4-$C$7)<=$C$9),1,0) -> 1 | ... AW8: =+IF(AND(AW$6=0,(AW$4-$C$7)<=$C$9),1,0) -> 0
A9: Operating year number | B9: # | C9: =+Inputs!F21 -> 30 | D9: 1 in first operating year | E9: =IF(E$4<=$C$9+$C$7,E8,0) -> 0 | F9: =IF(F$4<=$C$9+$C$7,E9+F8,0) -> 0 | G9: =IF(G$4<=$C$9+$C$7,F9+G8,0) -> 1 | H9: =IF(H$4<=$C$9+$C$7,G9+H8,0) -> 2 | I9: =IF(I$4<=$C$9+$C$7,H9+I8,0) -> 3 | J9: =IF(J$4<=$C$9+$C$7,I9+J8,0) -> 4 | K9: =IF(K$4<=$C$9+$C$7,J9+K8,0) -> 5 | L9: =IF(L$4<=$C$9+$C$7,K9+L8,0) -> 6 | M9: =IF(M$4<=$C$9+$C$7,L9+M8,0) -> 7 | ... AW9: =IF(AW$4<=$C$9+$C$7,AV9+AW8,0) -> 0
A10: Debt repayment flag | B10: 1/0 | C10: =+Inputs!$F$24 -> 27 | D10: Operating year <= debt tenor | E10: =+IF(AND(E$9>0,E$9<=$C$10),1,0) -> 0 | F10: =+IF(AND(F$9>0,F$9<=$C$10),1,0) -> 0 | G10: =+IF(AND(G$9>0,G$9<=$C$10),1,0) -> 1 | H10: =+IF(AND(H$9>0,H$9<=$C$10),1,0) -> 1 | I10: =+IF(AND(I$9>0,I$9<=$C$10),1,0) -> 1 | J10: =+IF(AND(J$9>0,J$9<=$C$10),1,0) -> 1 | K10: =+IF(AND(K$9>0,K$9<=$C$10),1,0) -> 1 | L10: =+IF(AND(L$9>0,L$9<=$C$10),1,0) -> 1 | ... AW10: =+IF(AND(AW$9>0,AW$9<=$C$10),1,0) -> 0
A11: Discount factor (to financial close) | B11: x | C11: =+Inputs!$F$34 -> 0.075 | D11: 1/(1+r)^(period); valuation date is financial close | E11: =1/(1+$C$11)^E$4 -> 0.93023256 | F11: =1/(1+$C$11)^F$4 -> 0.86533261 | G11: =1/(1+$C$11)^G$4 -> 0.80496057 | H11: =1/(1+$C$11)^H$4 -> 0.74880053 | I11: =1/(1+$C$11)^I$4 -> 0.69655863 | J11: =1/(1+$C$11)^J$4 -> 0.64796152 | K11: =1/(1+$C$11)^K$4 -> 0.6027549 | L11: =1/(1+$C$11)^L$4 -> 0.56070223 | ... AW11: =1/(1+$C$11)^AW$4 -> 0.038602827

Sheet Operations
A1: Operations
A2: Generation, revenue and operating costs.
A4: Line (period number across) | B4: Unit | C4: Year 1 value | D4: Spec note | E4: 1 | F4: 2 | G4: 3 | H4: 4 | I4: 5 | J4: 6 | K4: 7 | L4: 8 | M4: 9 | N4: 10 | O4: 11 | P4: 12 | Q4: 13 | R4: 14 | S4: 15 | T4: 16 | U4: 17 | V4: 18 | W4: 19 | X4: 20 | Y4: 21 | Z4: 22 | AA4: 23 | AB4: 24 | AC4: 25 | AD4: 26 | AE4: 27 | AF4: 28 | AG4: 29 | AH4: 30 | AI4: 31 | AJ4: 32 | AK4: 33 | AL4: 34 | AM4: 35 | AN4: 36 | AO4: 37 | AP4: 38 | AQ4: 39 | AR4: 40 | AS4: 41 | AT4: 42 | AU4: 43 | AV4: 44 | AW4: 45
A5: Generation
A6: DC capacity | B6: MWp | C6: =+Inputs!$F$8*Inputs!$F$9 -> 1300 | D6: MWac x DC/AC
A7: Generation | B7: MWh | C7: =+$C$6*Inputs!$F$10 -> 2912000 | D7: MWp x yield x (1-degradation)^(operating year-1) x ops flag | E7: =+$C$7*(1-Inputs!$F$11)^(Timeline!E$9-1)*Timeline!E$8 -> 0 | F7: =+$C$7*(1-Inputs!$F$11)^(Timeline!F$9-1)*Timeline!F$8 -> 0 | G7: =+$C$7*(1-Inputs!$F$11)^(Timeline!G$9-1)*Timeline!G$8 -> 2912000 | H7: =+$C$7*(1-Inputs!$F$11)^(Timeline!H$9-1)*Timeline!H$8 -> 2897440 | I7: =+$C$7*(1-Inputs!$F$11)^(Timeline!I$9-1)*Timeline!I$8 -> 2882952.8 | J7: =+$C$7*(1-Inputs!$F$11)^(Timeline!J$9-1)*Timeline!J$8 -> 2868538 | K7: =+$C$7*(1-Inputs!$F$11)^(Timeline!K$9-1)*Timeline!K$8 -> 2854195.3 | L7: =+$C$7*(1-Inputs!$F$11)^(Timeline!L$9-1)*Timeline!L$8 -> 2839924.4 | ... AW7: =+$C$7*(1-Inputs!$F$11)^(Timeline!AW$9-1)*Timeline!AW$8 -> 0
A8: Revenue and costs
A9: Tariff | B9: USD/MWh | C9: =+Inputs!$F$20*10 -> 14.1 | D9: US cents/kWh x 10 | E9: =+$C$9 -> 14.1 | F9: =+$C$9 -> 14.1 | G9: =+$C$9 -> 14.1 | H9: =+$C$9 -> 14.1 | I9: =+$C$9 -> 14.1 | J9: =+$C$9 -> 14.1 | K9: =+$C$9 -> 14.1 | L9: =+$C$9 -> 14.1 | ... AW9: =+$C$9 -> 14.1
A10: Revenue | B10: USD | C10: =+C9*C7 -> 41059200 | E10: =+E9*E7 -> 0 | F10: =+F9*F7 -> 0 | G10: =+G9*G7 -> 41059200 | H10: =+H9*H7 -> 40853904 | I10: =+I9*I7 -> 40649634 | J10: =+J9*J7 -> 40446386 | K10: =+K9*K7 -> 40244154 | L10: =+L9*L7 -> 40042934 | ... AW10: =+AW9*AW7 -> 0
A11: O&M cost | B11: USD | C11: =+Inputs!$F$8*1000*Inputs!$F$18 -> 11000000 | E11: =+$C$11*Timeline!E$8 -> 0 | F11: =+$C$11*Timeline!F$8 -> 0 | G11: =+$C$11*Timeline!G$8 -> 11000000 | H11: =+$C$11*Timeline!H$8 -> 11000000 | I11: =+$C$11*Timeline!I$8 -> 11000000 | J11: =+$C$11*Timeline!J$8 -> 11000000 | K11: =+$C$11*Timeline!K$8 -> 11000000 | L11: =+$C$11*Timeline!L$8 -> 11000000 | ... AW11: =+$C$11*Timeline!AW$8 -> 0
A12: EBITDA | B12: USD | C12: =+C10-C11 -> 30059200 | E12: =+E10-E11 -> 0 | F12: =+F10-F11 -> 0 | G12: =+G10-G11 -> 30059200 | H12: =+H10-H11 -> 29853904 | I12: =+I10-I11 -> 29649634 | J12: =+J10-J11 -> 29446386 | K12: =+K10-K11 -> 29244154 | L12: =+L10-L11 -> 29042934 | ... AW12: =+AW10-AW11 -> 0

Sheet Debt
A1: Debt
A2: Construction funding, interest during construction, and repayment.
A4: Line (period number across) | B4: Unit | C4: Total / value | D4: Spec note | E4: 1 | F4: 2 | G4: 3 | H4: 4 | I4: 5 | J4: 6 | K4: 7 | L4: 8 | M4: 9 | N4: 10 | O4: 11 | P4: 12 | Q4: 13 | R4: 14 | S4: 15 | T4: 16 | U4: 17 | V4: 18 | W4: 19 | X4: 20 | Y4: 21 | Z4: 22 | AA4: 23 | AB4: 24 | AC4: 25 | AD4: 26 | AE4: 27 | AF4: 28 | AG4: 29 | AH4: 30 | AI4: 31 | AJ4: 32 | AK4: 33 | AL4: 34 | AM4: 35 | AN4: 36 | AO4: 37 | AP4: 38 | AQ4: 39 | AR4: 40 | AS4: 41 | AT4: 42 | AU4: 43 | AV4: 44 | AW4: 45
A5: Construction funding
A6: Capex spend | B6: USD | C6: =+Inputs!$F$17*Inputs!$F$8*1000 -> 550000000 | D6: Capex x phasing x construction year | E6: =+$C$6*Timeline!E$6*Inputs!$F$14 -> 220000000 | F6: =+$C$6*Timeline!F$6*Inputs!$F$15 -> 330000000 | G6: =+$C$6*Timeline!G$6 -> 0 | H6: =+$C$6*Timeline!H$6 -> 0 | I6: =+$C$6*Timeline!I$6 -> 0 | J6: =+$C$6*Timeline!J$6 -> 0 | K6: =+$C$6*Timeline!K$6 -> 0 | L6: =+$C$6*Timeline!L$6 -> 0 | M6: =+$C$6*Timeline!M$6 -> 0 | N6: =+$C$6*Timeline!N$6 -> 0 | ... AW6: =+$C$6*Timeline!AW$6 -> 0
A7: Debt drawdown (capex share) | B7: USD | C7: =+C6*Inputs!$F$23 -> 396000000 | D7: Capex spend x gearing | E7: =+E$6*Inputs!$F$23 -> 158400000 | F7: =+F$6*Inputs!$F$23 -> 237600000 | G7: =+G$6*Inputs!$F$23 -> 0 | H7: =+H$6*Inputs!$F$23 -> 0 | I7: =+I$6*Inputs!$F$23 -> 0 | J7: =+J$6*Inputs!$F$23 -> 0 | K7: =+K$6*Inputs!$F$23 -> 0 | L7: =+L$6*Inputs!$F$23 -> 0 | ... AW7: =+AW$6*Inputs!$F$23 -> 0
A8: Equity contribution | B8: USD | C8: =+C6-C7 -> 154000000 | D8: Capex spend - debt drawdown | E8: =+E6-E7 -> 61600000 | F8: =+F6-F7 -> 92400000 | G8: =+G6-G7 -> 0 | H8: =+H6-H7 -> 0 | I8: =+I6-I7 -> 0 | J8: =+J6-J7 -> 0 | K8: =+K6-K7 -> 0 | L8: =+L6-L7 -> 0 | ... AW8: =+AW6-AW7 -> 0
A9: Interest during construction (capitalised) | B9: USD | C9: =+SUM(E9:AW9) -> 9662400 | D9: Cumulative prior drawdowns (incl. capitalised interest) × rate × construction flag | E9: =+SUM($D$12:D12)*Inputs!$F$25*Timeline!E$6 -> 0 | F9: =+SUM($D$12:E12)*Inputs!$F$25*Timeline!F$6 -> 9662400 | G9: =+SUM($D$12:F12)*Inputs!$F$25*Timeline!G$6 -> 0 | H9: =+SUM($D$12:G12)*Inputs!$F$25*Timeline!H$6 -> 0 | I9: =+SUM($D$12:H12)*Inputs!$F$25*Timeline!I$6 -> 0 | J9: =+SUM($D$12:I12)*Inputs!$F$25*Timeline!J$6 -> 0 | K9: =+SUM($D$12:J12)*Inputs!$F$25*Timeline!K$6 -> 0 | L9: =+SUM($D$12:K12)*Inputs!$F$25*Timeline!L$6 -> 0 | ... AW9: =+SUM($D$12:AV12)*Inputs!$F$25*Timeline!AW$6 -> 0
A10: Loan account
A11: Opening balance | B11: USD | D11: Previous closing balance | E11: 0 | F11: =+E16 -> 158400000 | G11: =+F16 -> 405662400 | H11: =+G16 -> 3.993925e+08 | I11: =+H16 -> 3.9274013e+08 | J11: =+I16 -> 3.8568197e+08 | K11: =+J16 -> 3.7819326e+08 | L11: =+K16 -> 3.7024775e+08 | M11: =+L16 -> 3.6181755e+08 | ... AW11: =+AV16 -> 3.2036036e-07
A12: Drawdown incl. capitalised interest | B12: USD | D12: Construction years only | E12: =+E7+E9 -> 158400000 | F12: =+F7+F9 -> 247262400 | G12: =+G7+G9 -> 0 | H12: =+H7+H9 -> 0 | I12: =+I7+I9 -> 0 | J12: =+J7+J9 -> 0 | K12: =+K7+K9 -> 0 | L12: =+L7+L9 -> 0 | ... AW12: =+AW7+AW9 -> 0
A13: Debt service (annuity) | B13: USD | C13: =+PMT(Inputs!$F$25, Inputs!$F$24, -SUM(Debt!$E$12:$AW$12)) -> 31015308 | D13: PMT on balance at COD x repayment flag | E13: =+IF(Timeline!E$10=1,Debt!$C$13*Timeline!E$10,0) -> 0 | F13: =+IF(Timeline!F$10=1,Debt!$C$13*Timeline!F$10,0) -> 0 | G13: =+IF(Timeline!G$10=1,Debt!$C$13*Timeline!G$10,0) -> 31015308 | H13: =+IF(Timeline!H$10=1,Debt!$C$13*Timeline!H$10,0) -> 31015308 | I13: =+IF(Timeline!I$10=1,Debt!$C$13*Timeline!I$10,0) -> 31015308 | J13: =+IF(Timeline!J$10=1,Debt!$C$13*Timeline!J$10,0) -> 31015308 | K13: =+IF(Timeline!K$10=1,Debt!$C$13*Timeline!K$10,0) -> 31015308 | L13: =+IF(Timeline!L$10=1,Debt!$C$13*Timeline!L$10,0) -> 31015308 | ... AW13: =+IF(Timeline!AW$10=1,Debt!$C$13*Timeline!AW$10,0) -> 0
A14: Interest paid | B14: USD | D14: Opening balance x rate, operating years | E14: =+E11*Inputs!$F$25*Timeline!E$8 -> 0 | F14: =+F11*Inputs!$F$25*Timeline!F$8 -> 0 | G14: =+G11*Inputs!$F$25*Timeline!G$8 -> 24745406 | H14: =+H11*Inputs!$F$25*Timeline!H$8 -> 24362942 | I14: =+I11*Inputs!$F$25*Timeline!I$8 -> 23957148 | J14: =+J11*Inputs!$F$25*Timeline!J$8 -> 23526600 | K14: =+K11*Inputs!$F$25*Timeline!K$8 -> 23069789 | L14: =+L11*Inputs!$F$25*Timeline!L$8 -> 22585112 | ... AW14: =+AW11*Inputs!$F$25*Timeline!AW$8 -> 0
A15: Principal repaid | B15: USD | D15: Debt service - interest | E15: =+E13-E14 -> 0 | F15: =+F13-F14 -> 0 | G15: =+G13-G14 -> 6269901.7 | H15: =+H13-H14 -> 6652365.7 | I15: =+I13-I14 -> 7058160.1 | J15: =+J13-J14 -> 7488707.8 | K15: =+K13-K14 -> 7945519 | L15: =+L13-L14 -> 8430195.7 | ... AW15: =+AW13-AW14 -> 0
A16: Closing balance | B16: USD | D16: Opening + drawdown - principal | E16: =+E$11+E$12-E$15 -> 158400000 | F16: =+F$11+F$12-F$15 -> 405662400 | G16: =+G$11+G$12-G$15 -> 3.993925e+08 | H16: =+H$11+H$12-H$15 -> 3.9274013e+08 | I16: =+I$11+I$12-I$15 -> 3.8568197e+08 | J16: =+J$11+J$12-J$15 -> 3.7819326e+08 | K16: =+K$11+K$12-K$15 -> 3.7024775e+08 | L16: =+L$11+L$12-L$15 -> 3.6181755e+08 | ... AW16: =+AW$11+AW$12-AW$15 -> 3.2036036e-07

Sheet Tax
A1: Tax
A2: Depreciation and tax/zakat, levered and unlevered.
A4: Line (period number across) | B4: Unit | C4: Total / value | D4: Spec note | E4: 1 | F4: 2 | G4: 3 | H4: 4 | I4: 5 | J4: 6 | K4: 7 | L4: 8 | M4: 9 | N4: 10 | O4: 11 | P4: 12 | Q4: 13 | R4: 14 | S4: 15 | T4: 16 | U4: 17 | V4: 18 | W4: 19 | X4: 20 | Y4: 21 | Z4: 22 | AA4: 23 | AB4: 24 | AC4: 25 | AD4: 26 | AE4: 27 | AF4: 28 | AG4: 29 | AH4: 30 | AI4: 31 | AJ4: 32 | AK4: 33 | AL4: 34 | AM4: 35 | AN4: 36 | AO4: 37 | AP4: 38 | AQ4: 39 | AR4: 40 | AS4: 41 | AT4: 42 | AU4: 43 | AV4: 44 | AW4: 45
A5: Depreciation
A6: Depreciable base (capex + capitalised interest) | B6: USD | C6: =+SUM(Debt!$E$6:$AW$6)+SUM(Debt!$E$9:$AW$9) -> 559662400 | D6: Single value
A7: Depreciation | B7: USD | D7: base / project life, operating years | E7: =+$C$6/Inputs!$F$35*Timeline!E$8 -> 0 | F7: =+$C$6/Inputs!$F$35*Timeline!F$8 -> 0 | G7: =+$C$6/Inputs!$F$35*Timeline!G$8 -> 18655413 | H7: =+$C$6/Inputs!$F$35*Timeline!H$8 -> 18655413 | I7: =+$C$6/Inputs!$F$35*Timeline!I$8 -> 18655413 | J7: =+$C$6/Inputs!$F$35*Timeline!J$8 -> 18655413 | K7: =+$C$6/Inputs!$F$35*Timeline!K$8 -> 18655413 | L7: =+$C$6/Inputs!$F$35*Timeline!L$8 -> 18655413 | ... AW7: =+$C$6/Inputs!$F$35*Timeline!AW$8 -> 0
A8: Levered (for equity and CFADS)
A9: Taxable income | B9: USD | D9: EBITDA - interest - depreciation | E9: =+Operations!E$12-Debt!E$14-Tax!E$7 -> 0 | F9: =+Operations!F$12-Debt!F$14-Tax!F$7 -> 0 | G9: =+Operations!G$12-Debt!G$14-Tax!G$7 -> -13341620 | H9: =+Operations!H$12-Debt!H$14-Tax!H$7 -> -13164452 | I9: =+Operations!I$12-Debt!I$14-Tax!I$7 -> -12962927 | J9: =+Operations!J$12-Debt!J$14-Tax!J$7 -> -12735627 | K9: =+Operations!K$12-Debt!K$14-Tax!K$7 -> -12481048 | L9: =+Operations!L$12-Debt!L$14-Tax!L$7 -> -12197592 | ... AW9: =+Operations!AW$12-Debt!AW$14-Tax!AW$7 -> 0
A10: Tax: KSA (income tax + zakat proxy) | B10: USD | E10: =+MAX(E$9,0)*((Inputs!$F$27*Inputs!$F$29)+(Inputs!$F$28*(1-Inputs!$F$29))) -> 0 | F10: =+MAX(F$9,0)*((Inputs!$F$27*Inputs!$F$29)+(Inputs!$F$28*(1-Inputs!$F$29))) -> 0 | G10: =+MAX(G$9,0)*((Inputs!$F$27*Inputs!$F$29)+(Inputs!$F$28*(1-Inputs!$F$29))) -> 0 | H10: =+MAX(H$9,0)*((Inputs!$F$27*Inputs!$F$29)+(Inputs!$F$28*(1-Inputs!$F$29))) -> 0 | I10: =+MAX(I$9,0)*((Inputs!$F$27*Inputs!$F$29)+(Inputs!$F$28*(1-Inputs!$F$29))) -> 0 | J10: =+MAX(J$9,0)*((Inputs!$F$27*Inputs!$F$29)+(Inputs!$F$28*(1-Inputs!$F$29))) -> 0 | K10: =+MAX(K$9,0)*((Inputs!$F$27*Inputs!$F$29)+(Inputs!$F$28*(1-Inputs!$F$29))) -> 0 | L10: =+MAX(L$9,0)*((Inputs!$F$27*Inputs!$F$29)+(Inputs!$F$28*(1-Inputs!$F$29))) -> 0 | ... AW10: =+MAX(AW$9,0)*((Inputs!$F$27*Inputs!$F$29)+(Inputs!$F$28*(1-Inputs!$F$29))) -> 0
A11: Tax: UAE | B11: USD | D11: Threshold converted at AED 3.6725 | E11: =+IF(Tax!E$9>(Inputs!$E$31/Inputs!$E$32),(Tax!E$9-Inputs!$E$31/Inputs!$E$32)*Inputs!$F$30,0) -> 0 | F11: =+IF(Tax!F$9>(Inputs!$E$31/Inputs!$E$32),(Tax!F$9-Inputs!$E$31/Inputs!$E$32)*Inputs!$F$30,0) -> 0 | G11: =+IF(Tax!G$9>(Inputs!$E$31/Inputs!$E$32),(Tax!G$9-Inputs!$E$31/Inputs!$E$32)*Inputs!$F$30,0) -> 0 | H11: =+IF(Tax!H$9>(Inputs!$E$31/Inputs!$E$32),(Tax!H$9-Inputs!$E$31/Inputs!$E$32)*Inputs!$F$30,0) -> 0 | I11: =+IF(Tax!I$9>(Inputs!$E$31/Inputs!$E$32),(Tax!I$9-Inputs!$E$31/Inputs!$E$32)*Inputs!$F$30,0) -> 0 | J11: =+IF(Tax!J$9>(Inputs!$E$31/Inputs!$E$32),(Tax!J$9-Inputs!$E$31/Inputs!$E$32)*Inputs!$F$30,0) -> 0 | K11: =+IF(Tax!K$9>(Inputs!$E$31/Inputs!$E$32),(Tax!K$9-Inputs!$E$31/Inputs!$E$32)*Inputs!$F$30,0) -> 0 | L11: =+IF(Tax!L$9>(Inputs!$E$31/Inputs!$E$32),(Tax!L$9-Inputs!$E$31/Inputs!$E$32)*Inputs!$F$30,0) -> 0 | ... AW11: =+IF(Tax!AW$9>(Inputs!$E$31/Inputs!$E$32),(Tax!AW$9-Inputs!$E$31/Inputs!$E$32)*Inputs!$F$30,0) -> 0
A12: Tax: selected country | B12: USD | E12: =+SUM(E10:E11) -> 0 | F12: =+SUM(F10:F11) -> 0 | G12: =+SUM(G10:G11) -> 0 | H12: =+SUM(H10:H11) -> 0 | I12: =+SUM(I10:I11) -> 0 | J12: =+SUM(J10:J11) -> 0 | K12: =+SUM(K10:K11) -> 0 | L12: =+SUM(L10:L11) -> 0 | ... AW12: =+SUM(AW10:AW11) -> 0
A13: Unlevered (for project returns)
A14: Unlevered taxable income | B14: USD | D14: EBITDA - depreciation | E14: =+Operations!E$12-Tax!E$7 -> 0 | F14: =+Operations!F$12-Tax!F$7 -> 0 | G14: =+Operations!G$12-Tax!G$7 -> 11403787 | H14: =+Operations!H$12-Tax!H$7 -> 11198491 | I14: =+Operations!I$12-Tax!I$7 -> 10994221 | J14: =+Operations!J$12-Tax!J$7 -> 10790973 | K14: =+Operations!K$12-Tax!K$7 -> 10588741 | L14: =+Operations!L$12-Tax!L$7 -> 10387520 | ... AW14: =+Operations!AW$12-Tax!AW$7 -> 0
A15: Unlevered tax: KSA (income tax + zakat proxy) | B15: USD | E15: =+MAX(E$14,0)*((Inputs!$F$27*Inputs!$F$29)+(Inputs!$F$28*(1-Inputs!$F$29))) -> 0 | F15: =+MAX(F$14,0)*((Inputs!$F$27*Inputs!$F$29)+(Inputs!$F$28*(1-Inputs!$F$29))) -> 0 | G15: =+MAX(G$14,0)*((Inputs!$F$27*Inputs!$F$29)+(Inputs!$F$28*(1-Inputs!$F$29))) -> 0 | H15: =+MAX(H$14,0)*((Inputs!$F$27*Inputs!$F$29)+(Inputs!$F$28*(1-Inputs!$F$29))) -> 0 | I15: =+MAX(I$14,0)*((Inputs!$F$27*Inputs!$F$29)+(Inputs!$F$28*(1-Inputs!$F$29))) -> 0 | J15: =+MAX(J$14,0)*((Inputs!$F$27*Inputs!$F$29)+(Inputs!$F$28*(1-Inputs!$F$29))) -> 0 | K15: =+MAX(K$14,0)*((Inputs!$F$27*Inputs!$F$29)+(Inputs!$F$28*(1-Inputs!$F$29))) -> 0 | L15: =+MAX(L$14,0)*((Inputs!$F$27*Inputs!$F$29)+(Inputs!$F$28*(1-Inputs!$F$29))) -> 0 | ... AW15: =+MAX(AW$14,0)*((Inputs!$F$27*Inputs!$F$29)+(Inputs!$F$28*(1-Inputs!$F$29))) -> 0
A16: Unlevered tax: UAE | B16: USD | E16: =+IF(Tax!E$14>(Inputs!$E$31/Inputs!$E$32),(Tax!E$14-Inputs!$E$31/Inputs!$E$32)*Inputs!$F$30,0) -> 0 | F16: =+IF(Tax!F$14>(Inputs!$E$31/Inputs!$E$32),(Tax!F$14-Inputs!$E$31/Inputs!$E$32)*Inputs!$F$30,0) -> 0 | G16: =+IF(Tax!G$14>(Inputs!$E$31/Inputs!$E$32),(Tax!G$14-Inputs!$E$31/Inputs!$E$32)*Inputs!$F$30,0) -> 1017150.9 | H16: =+IF(Tax!H$14>(Inputs!$E$31/Inputs!$E$32),(Tax!H$14-Inputs!$E$31/Inputs!$E$32)*Inputs!$F$30,0) -> 998674.23 | I16: =+IF(Tax!I$14>(Inputs!$E$31/Inputs!$E$32),(Tax!I$14-Inputs!$E$31/Inputs!$E$32)*Inputs!$F$30,0) -> 980289.98 | J16: =+IF(Tax!J$14>(Inputs!$E$31/Inputs!$E$32),(Tax!J$14-Inputs!$E$31/Inputs!$E$32)*Inputs!$F$30,0) -> 961997.64 | K16: =+IF(Tax!K$14>(Inputs!$E$31/Inputs!$E$32),(Tax!K$14-Inputs!$E$31/Inputs!$E$32)*Inputs!$F$30,0) -> 943796.77 | L16: =+IF(Tax!L$14>(Inputs!$E$31/Inputs!$E$32),(Tax!L$14-Inputs!$E$31/Inputs!$E$32)*Inputs!$F$30,0) -> 925686.9 | ... AW16: =+IF(Tax!AW$14>(Inputs!$E$31/Inputs!$E$32),(Tax!AW$14-Inputs!$E$31/Inputs!$E$32)*Inputs!$F$30,0) -> 0
A17: Unlevered tax: selected country | B17: USD | E17: =+SUM(E15:E16) -> 0 | F17: =+SUM(F15:F16) -> 0 | G17: =+SUM(G15:G16) -> 1017150.9 | H17: =+SUM(H15:H16) -> 998674.23 | I17: =+SUM(I15:I16) -> 980289.98 | J17: =+SUM(J15:J16) -> 961997.64 | K17: =+SUM(K15:K16) -> 943796.77 | L17: =+SUM(L15:L16) -> 925686.9 | ... AW17: =+SUM(AW15:AW16) -> 0

Sheet CashFlow
A1: CashFlow
A2: Cash available for debt service, DSCR and the two return streams.
A4: Line (period number across) | B4: Unit | C4: Total / value | D4: Spec note | E4: 1 | F4: 2 | G4: 3 | H4: 4 | I4: 5 | J4: 6 | K4: 7 | L4: 8 | M4: 9 | N4: 10 | O4: 11 | P4: 12 | Q4: 13 | R4: 14 | S4: 15 | T4: 16 | U4: 17 | V4: 18 | W4: 19 | X4: 20 | Y4: 21 | Z4: 22 | AA4: 23 | AB4: 24 | AC4: 25 | AD4: 26 | AE4: 27 | AF4: 28 | AG4: 29 | AH4: 30 | AI4: 31 | AJ4: 32 | AK4: 33 | AL4: 34 | AM4: 35 | AN4: 36 | AO4: 37 | AP4: 38 | AQ4: 39 | AR4: 40 | AS4: 41 | AT4: 42 | AU4: 43 | AV4: 44 | AW4: 45
A5: Debt cover
A6: CFADS | B6: USD | C6: =+SUM(E6:AW6) -> 8.1405743e+08 | D6: EBITDA - tax | E6: =+Operations!E$12-Tax!E$12 -> 0 | F6: =+Operations!F$12-Tax!F$12 -> 0 | G6: =+Operations!G$12-Tax!G$12 -> 30059200 | H6: =+Operations!H$12-Tax!H$12 -> 29853904 | I6: =+Operations!I$12-Tax!I$12 -> 29649634 | J6: =+Operations!J$12-Tax!J$12 -> 29446386 | K6: =+Operations!K$12-Tax!K$12 -> 29244154 | L6: =+Operations!L$12-Tax!L$12 -> 29042934 | ... AW6: =+Operations!AW$12-Tax!AW$12 -> 0
A7: Debt service | B7: USD | C7: =+SUM(E7:AW7) -> 8.3741332e+08 | D7: Link from Debt | E7: =+Debt!E$13 -> 0 | F7: =+Debt!F$13 -> 0 | G7: =+Debt!G$13 -> 31015308 | H7: =+Debt!H$13 -> 31015308 | I7: =+Debt!I$13 -> 31015308 | J7: =+Debt!J$13 -> 31015308 | K7: =+Debt!K$13 -> 31015308 | L7: =+Debt!L$13 -> 31015308 | ... AW7: =+Debt!AW$13 -> 0
A8: DSCR | B8: x | D8: Debt years only (blank otherwise) | E8: =+IF(E$7<>0,E$6/E$7,"") | F8: =+IF(F$7<>0,F$6/F$7,"") | G8: =+IF(G$7<>0,G$6/G$7,"") -> 0.96917302 | H8: =+IF(H$7<>0,H$6/H$7,"") -> 0.96255384 | I8: =+IF(I$7<>0,I$6/I$7,"") -> 0.95596775 | J8: =+IF(J$7<>0,J$6/J$7,"") -> 0.9494146 | K8: =+IF(K$7<>0,K$6/K$7,"") -> 0.94289421 | L8: =+IF(L$7<>0,L$6/L$7,"") -> 0.93640642 | ... AW8: =+IF(AW$7<>0,AW$6/AW$7,"")
A9: Returns
A10: Equity cash flow | B10: USD | C10: =+SUM(E10:AW10) -> -1.7735589e+08 | D10: -equity in construction; CFADS - debt service after | E10: =-Debt!E$8+CashFlow!E$6-CashFlow!E$7 -> -61600000 | F10: =-Debt!F$8+CashFlow!F$6-CashFlow!F$7 -> -92400000 | G10: =-Debt!G$8+CashFlow!G$6-CashFlow!G$7 -> -956108.14 | H10: =-Debt!H$8+CashFlow!H$6-CashFlow!H$7 -> -1161404.1 | I10: =-Debt!I$8+CashFlow!I$6-CashFlow!I$7 -> -1365673.7 | J10: =-Debt!J$8+CashFlow!J$6-CashFlow!J$7 -> -1568921.8 | K10: =-Debt!K$8+CashFlow!K$6-CashFlow!K$7 -> -1771153.8 | L10: =-Debt!L$8+CashFlow!L$6-CashFlow!L$7 -> -1972374.5 | ... AW10: =-Debt!AW$8+CashFlow!AW$6-CashFlow!AW$7 -> 0
A11: Project cash flow (unlevered, after tax) | B11: USD | C11: =+SUM(E11:AW11) -> 2.4366275e+08 | D11: -capex in construction; EBITDA - unlevered tax after | E11: =-Debt!E$6+Operations!E$12-Tax!E$17 -> -220000000 | F11: =-Debt!F$6+Operations!F$12-Tax!F$17 -> -330000000 | G11: =-Debt!G$6+Operations!G$12-Tax!G$17 -> 29042049 | H11: =-Debt!H$6+Operations!H$12-Tax!H$17 -> 28855230 | I11: =-Debt!I$6+Operations!I$12-Tax!I$17 -> 28669345 | J11: =-Debt!J$6+Operations!J$12-Tax!J$17 -> 28484389 | K11: =-Debt!K$6+Operations!K$12-Tax!K$17 -> 28300358 | L11: =-Debt!L$6+Operations!L$12-Tax!L$17 -> 28117247 | ... AW11: =-Debt!AW$6+Operations!AW$12-Tax!AW$17 -> 0
A12: For LCOE (discounted to financial close)
A13: Discounted capex | B13: USD | C13: =+SUM(E13:AW13) -> 4.9021092e+08 | D13: Capex spend x discount factor | E13: =+Debt!E$6*Timeline!E$11 -> 2.0465116e+08 | F13: =+Debt!F$6*Timeline!F$11 -> 2.8555976e+08 | G13: =+Debt!G$6*Timeline!G$11 -> 0 | H13: =+Debt!H$6*Timeline!H$11 -> 0 | I13: =+Debt!I$6*Timeline!I$11 -> 0 | J13: =+Debt!J$6*Timeline!J$11 -> 0 | K13: =+Debt!K$6*Timeline!K$11 -> 0 | L13: =+Debt!L$6*Timeline!L$11 -> 0 | ... AW13: =+Debt!AW$6*Timeline!AW$11 -> 0
A14: Discounted O&M | B14: USD | C14: =+SUM(E14:AW14) -> 1.1241904e+08 | D14: O&M x discount factor | E14: =+Operations!E$11*Timeline!E$11 -> 0 | F14: =+Operations!F$11*Timeline!F$11 -> 0 | G14: =+Operations!G$11*Timeline!G$11 -> 8854566.3 | H14: =+Operations!H$11*Timeline!H$11 -> 8236805.8 | I14: =+Operations!I$11*Timeline!I$11 -> 7662145 | J14: =+Operations!J$11*Timeline!J$11 -> 7127576.7 | K14: =+Operations!K$11*Timeline!K$11 -> 6630303.9 | L14: =+Operations!L$11*Timeline!L$11 -> 6167724.6 | ... AW14: =+Operations!AW$11*Timeline!AW$11 -> 0
A15: Discounted generation | B15: MWh | C15: =+SUM(E15:AW15) -> 28402663 | D15: Generation x discount factor | E15: =+Operations!E$7*Timeline!E$11 -> 0 | F15: =+Operations!F$7*Timeline!F$11 -> 0 | G15: =+Operations!G$7*Timeline!G$11 -> 2344045.2 | H15: =+Operations!H$7*Timeline!H$11 -> 2169604.6 | I15: =+Operations!I$7*Timeline!I$11 -> 2008145.7 | J15: =+Operations!J$7*Timeline!J$11 -> 1858702.3 | K15: =+Operations!K$7*Timeline!K$11 -> 1720380.2 | L15: =+Operations!L$7*Timeline!L$11 -> 1592351.9 | ... AW15: =+Operations!AW$7*Timeline!AW$11 -> 0

Sheet Outputs
A1: Outputs
A2: Headline results for the selected country.
A4: Metric | B4: Unit | C4: Value | D4: Value | E4: Notes
A5: Headline results
A6: Country | C6: =+Inputs!$D$4 -> UAE | E6: Link to Inputs!D4
A7: LCOE | B7: USD/MWh | C7: =+(CashFlow!C$13+CashFlow!C$14)/CashFlow!C$15 -> 21.217375 | E7: Step 19: (disc. capex + disc. O&M) / disc. generation
A8: LCOE | B8: US cents/kWh | C8: =+$C$7/10 -> 2.1217375 | E8: LCOE / 10
A9: PPA tariff | B9: US cents/kWh | C9: =+Inputs!$F$20 -> 1.41 | E9: Link to Inputs
A10: Tariff minus LCOE | B10: US cents/kWh | C10: =+C9-C8 -> -0.71173753 | E10: Positive = tariff covers cost at this discount rate
A11: Project IRR (unlevered, after tax) | B11: % | C11: =+IRR(CashFlow!$E$11:$AW$11) -> 0.02566585 | E11: IRR of project cash flow
A12: Equity IRR | B12: % | C12: =+IRR(CashFlow!$E$10:$AW$10) -> -0.062835797 | E12: IRR of equity cash flow
A13: Project NPV at discount rate | B13: USD | C13: =+NPV(Inputs!$F$34,CashFlow!$E$11:$AW$11) -> -2.1082466e+08 | E13: Remember NPV() treats the first value as one period out
A14: Minimum DSCR | B14: x | C14: =+MIN(CashFlow!$E$8:$AW$8) -> 0.79435 | E14: MIN of DSCR row
A15: Average DSCR | B15: x | C15: =+AVERAGE(CashFlow!$E$8:$AW$8) -> 0.88559437 | E15: AVERAGE of DSCR row
A16: Size and funding
A17: Total capex | B17: USD | C17: =+SUM(Debt!$E$6:$AW$6) -> 550000000
A18: Capitalised interest during construction | B18: USD | C18: =+SUM(Debt!$E$9:$AW$9) -> 9662400
A19: Total debt at COD | B19: USD | C19: =+SUM(Debt!$E$7:$AW$7)+SUM(Debt!$E$9:$AW$9) -> 405662400
A20: Total equity | B20: USD | C20: =+SUM(Debt!$E$8:$AW$8) -> 154000000
A21: Effective gearing at COD | B21: % | C21: =+C19/(C17+C18) -> 0.72483411 | E21: Above input gearing because of capitalised interest
A22: Year-1 generation | B22: MWh | C22: =+Operations!$G$7 -> 2912000
A23: Capacity factor (AC basis) | B23: % | C23: =+C22/(Inputs!$F$8*8760) -> 0.33242009 | E23: Year-1 MWh / (MWac x 8,760)
A24: Solve-for (Data > What-If Analysis > Goal Seek; record results here)
A25: Country | C25: KSA | D25: UAE
A26: Tariff for target equity IRR | B26: US cents/kWh | C26: 1.8125863 | D26: 2.0082624 | E26: Goal Seek: equity IRR = target by changing the KSA/UAE tariff input
A27: Tariff for target minimum DSCR | B27: US cents/kWh | C27: 1.8023759 | D27: 1.9508723 | E27: Goal Seek: min DSCR = target
A28: Implied discount rate (LCOE = tariff) | B28: % | C28: 0.033356751 | D28: 0.027898531 | E28: Goal Seek: tariff minus LCOE = 0 by changing the discount rate
A29: Scenarios (record results)
A30: Country | C30: KSA | D30: UAE
A31: LCOE: base | B31: US cents/kWh | C31: 1.9439166 | D31: 2.1217375
A32: LCOE: conflict premium (+70 bp) | B32: US cents/kWh | C32: 2.0593585 | D32: 2.2415071
A33: LCOE: severe (+130 bp) | B33: US cents/kWh | C33: 2.1604266 | D33: 2.3465607
A35: Sensitivity (for the tornado): equity IRR and LCOE at each input's low and high
A36: KSA
A37: Driver | B37: Low input | C37: High input | D37: LCOE low (US cents/kWh) | E37: LCOE high (US cents/kWh) | F37: LCOE swing (US cents/kWh) | G37: Equity IRR low (%) | H37: Equity IRR high (%) | I37: Equity IRR swing (%)
A38: Capex | B38: =+Inputs!$G$17 -> 450 | C38: =+Inputs!$H$17 -> 725 | D38: 1.6573118 | E38: 2.445475 | F38: =+ABS(E38-D38) -> 0.78816326 | G38: 0.017896662 | H38: -0.087324028 | I38: =+ABS(H38-G38) -> 0.10522069
A39: Discount rate | B39: =+Inputs!$G$34 -> 0.06 | C39: =+Inputs!$D$34+Inputs!$D$40/10000 -> 0.09 | D39: 1.6761241 | E39: 2.1604266 | F39: =+ABS(E39-D39) -> 0.4843025 | G39: -0.030084704 | H39: -0.030084704 | I39: =+ABS(H39-G39) -> 0
A40: Specific yield (+/-10%) | B40: =+Inputs!$D$10*0.9 -> 2178 | C40: =+Inputs!$D$10*1.1 -> 2662 | D40: 2.1599073 | E40: 1.7671969 | F40: =+ABS(E40-D40) -> 0.39271042 | G40: -0.063160621 | H40: 0.00080891604 | I40: =+ABS(H40-G40) -> 0.063969537
A41: Debt rate | B41: =+Inputs!$G$25 -> 0.05 | C41: =+Inputs!$H$25 -> 0.075 | D41: 1.9439166 | E41: 1.9439166 | F41: =+ABS(E41-D41) -> 0 | G41: -0.0048067713 | H41: -0.061264419 | I41: =+ABS(H41-G41) -> 0.056457647
A42: Fixed O&M | B42: =+Inputs!$G$18 -> 9 | C42: =+Inputs!$H$18 -> 27 | D42: 1.877082 | E42: 2.4785931 | F42: =+ABS(E42-D42) -> 0.60151104 | G42: -0.013346572 | H42: -0.22969169 | I42: =+ABS(H42-G42) -> 0.21634512
...

Sheet Checks
A1: Checks
A2: Each check returns 0 when fine, 1 when broken.
A4: Check | B4: Result (0 = OK) | C4: Notes
A5: TOTAL (sum of all checks) | B5: =+SUM(B6:B15) -> 0 | C5: SUM of the column below
A6: Capex phasing sums to 100% | B6: =+IF(ABS(Inputs!F14+Inputs!F15-1)>0.0001,1,0) -> 0 | C6: ABS(y1 + y2 - 1) > 0.0001
A7: Sum of capex spend = total capex | B7: =+IF(ABS(SUM(Debt!E6:AW6)-Debt!C6)>1,1,0) -> 0
A8: Debt closing balance = 0 at end of tenor | B8: {=+IF(ABS(INDEX(Debt!E16:AW16, Inputs!F13+Inputs!F24))>1,1,0)} -> 0 | C8: ABS(final closing balance) > 1
A9: Total principal repaid = debt at COD | B9: =+IF(ABS(SUM(Debt!E15:AW15)-Outputs!C19)>1,1,0) -> 0
A10: Year-1 generation = MWp x yield | B10: =+IF(ABS(Operations!G7-Operations!C6*Inputs!F10)>1,1,0) -> 0
A11: No revenue outside operating years | B11: {=+IF(SUMPRODUCT(ABS(Operations!E10:AW10),1-Timeline!E8:AW8)>0,1,0)} -> 0
A12: No DSCR outside debt-repayment years | B12: {=+IF(SUMPRODUCT(--ISNUMBER(CashFlow!E8:AW8),1-Timeline!E10:AW10)>0,1,0)} -> 0
A13: NPV of equity cash flow at equity IRR = 0 | B13: =+IF(ABS(NPV(Outputs!C12,CashFlow!F10:AW10)+CashFlow!E10)>1,1,0) -> 0 | C13: Use NPV on periods 2+ plus period 1
A14: Only one country's tax is active | B14: {=+IF(SUMPRODUCT(ABS(Tax!E10:AW10)*ABS(Tax!E11:AW11))>0,1,0)} -> 0
A15: Construction period = 2 years (v1 lock) | B15: =+IF(Inputs!F13<>2,1,0) -> 0
